Traceback (most recent call last):
  File "/opt/homebrew/Caskroom/miniconda/base/envs/python311/lib/python3.11/site-packages/jupyter_cache/executors/utils.py", line 58, in single_nb_execution
    executenb(
  File "/opt/homebrew/Caskroom/miniconda/base/envs/python311/lib/python3.11/site-packages/nbclient/client.py", line 1305, in execute
    return NotebookClient(nb=nb, resources=resources, km=km, **kwargs).execute()
           ^^^^^^^^^^^^^^^^^^^^^^^^^^^^^^^^^^^^^^^^^^^^^^^^^^^^^^^^^^^^^^^^^^^^^
  File "/opt/homebrew/Caskroom/miniconda/base/envs/python311/lib/python3.11/site-packages/jupyter_core/utils/__init__.py", line 165, in wrapped
    return loop.run_until_complete(inner)
           ^^^^^^^^^^^^^^^^^^^^^^^^^^^^^^
  File "/opt/homebrew/Caskroom/miniconda/base/envs/python311/lib/python3.11/asyncio/base_events.py", line 650, in run_until_complete
    return future.result()
           ^^^^^^^^^^^^^^^
  File "/opt/homebrew/Caskroom/miniconda/base/envs/python311/lib/python3.11/contextlib.py", line 222, in __aexit__
    await self.gen.athrow(typ, value, traceback)
  File "/opt/homebrew/Caskroom/miniconda/base/envs/python311/lib/python3.11/site-packages/nbclient/client.py", line 650, in async_setup_kernel
    yield
  File "/opt/homebrew/Caskroom/miniconda/base/envs/python311/lib/python3.11/site-packages/nbclient/client.py", line 705, in async_execute
    await self.async_execute_cell(
  File "/opt/homebrew/Caskroom/miniconda/base/envs/python311/lib/python3.11/site-packages/nbclient/client.py", line 1058, in async_execute_cell
    await self._check_raise_for_error(cell, cell_index, exec_reply)
  File "/opt/homebrew/Caskroom/miniconda/base/envs/python311/lib/python3.11/site-packages/nbclient/client.py", line 914, in _check_raise_for_error
    raise CellExecutionError.from_cell_and_msg(cell, exec_reply_content)
nbclient.exceptions.CellExecutionError: An error occurred while executing the following cell:
------------------
import plotly.express as px 

fig = px.scatter(x=variation_zellengroesse, y=variation_fuellgrad,
    title='Variierte Eingabedaten um ausgewÃ¤hltes Referenzbeispiel (3, 0.3)'
)
fig.add_scatter(x=[3.0], y=[0.3], name='Referenz')
fig.update_layout(xaxis_range=[1.5, 4.5], yaxis_range=[0.15,0.45])
fig.save('variierte_eingabedaten.svg')
fig.show()
------------------


[0;31m---------------------------------------------------------------------------[0m
[0;31mAttributeError[0m                            Traceback (most recent call last)
Cell [0;32mIn[7], line 8[0m
[1;32m      6[0m fig[38;5;241m.[39madd_scatter(x[38;5;241m=[39m[[38;5;241m3.0[39m], y[38;5;241m=[39m[[38;5;241m0.3[39m], name[38;5;241m=[39m[38;5;124m'[39m[38;5;124mReferenz[39m[38;5;124m'[39m)
[1;32m      7[0m fig[38;5;241m.[39mupdate_layout(xaxis_range[38;5;241m=[39m[[38;5;241m1.5[39m, [38;5;241m4.5[39m], yaxis_range[38;5;241m=[39m[[38;5;241m0.15[39m,[38;5;241m0.45[39m])
[0;32m----> 8[0m fig[38;5;241m.[39msave([38;5;124m'[39m[38;5;124mvariierte_eingabedaten.svg[39m[38;5;124m'[39m)
[1;32m      9[0m fig[38;5;241m.[39mshow()

[0;31mAttributeError[0m: 'Figure' object has no attribute 'save'

